Workbook

Sheet Dissect
A1: ID | B1: Cohort | C1: Hatch | D1: Age | E1: Fin_sex | F1: Gonad_sex | G1: Tot_wgt | H1: Gonad_wgt | I1: GSI | J1: Egg_wgt | K1: Gonad_score | L1: Std_length | M1: Tot_length | N1: Fin_branch | O1: Dissect_date | P1: Dissect_time | Q1: Notes
A2: 1 | B2: Oct '19 | C2: 10/13-15/2019 | D2: 29 | E2: M | F2: M | G2: 0.323 | H2: 0.002 | I2: =H2/G2*100 -> 0.61919505 | K2: 3 | L2: 2.8 | M2: 3.5 | N2: 2 | O2: 44643 | P2: 0.48888889 | Q2: Did not record branching; Double assumed
A3: 2 | B3: Nov '19 | C3: 11/12-20/2019 | D3: 28 | E3: M | F3: M | G3: 0.3077 | H3: 0.0022 | I3: =H3/G3*100 -> 0.71498213 | K3: 3 | L3: 2.2 | M3: 2.9 | N3: 2 | O3: 44643 | P3: 0.48888889 | Q3: Did not record branching; Double assumed | W3: gonad scores: | X3: Male | Y3: Female
A4: 3 | B4: Dec '19 | C4: 12/16-20/2019 | D4: 27 | E4: M | F4: M | G4: 0.1738 | H4: 0.0003 | I4: =H4/G4*100 -> 0.1726122 | K4: 2 | L4: 2.1 | M4: 2.7 | N4: 2 | O4: 44643 | P4: 0.48888889 | Q4: Did not record branching; Double assumed | X4: 0 - not present | Y4: 0 - not present
A5: 4 | B5: Feb '20 | C5: 2/18-19/2020 | D5: 25 | E5: F | F5: F | G5: 0.2101 | H5: 0.03 | I5: =H5/G5*100 -> 14.278915 | K5: 3 | L5: 2 | M5: 2.7 | N5: 2 | O5: 44643 | P5: 0.48888889 | Q5: Did not record branching; Double assumed | X5: 1 - too small to collect | Y5: 1 - small, no large follicles (OR has very old follicles that are collaposed)
A6: 5 | B6: Apr '20 | C6: 4/17-24/2020 | D6: 23 | E6: F | F6: F | G6: 0.2434 | H6: 0.031 | I6: =H6/G6*100 -> 12.736237 | K6: 3 | L6: 2.2 | M6: 2.8 | N6: 2 | O6: 44643 | P6: 0.48888889 | Q6: Did not record branching; Double assumed | X6: 2 - small but collectable | Y6: 2 - normal, some large follicles
A7: 6 | B7: Jun '20 | C7: 6/17-25/2020 | D7: 21 | E7: F | F7: F | G7: 0.204 | H7: 0.0059 | I7: =H7/G7*100 -> 2.8921569 | K7: 1 | L7: 2.2 | M7: 2.8 | N7: 2 | O7: 44643 | P7: 0.48888889 | Q7: Did not record branching; Double assumed | X7: 3 - normal | Y7: 3 - large, many large follicles
A8: 7 | B8: Oct '19 | C8: 10/13-15/2019 | D8: 29 | E8: F | F8: F | G8: 0.2207 | H8: 0.0169 | I8: =H8/G8*100 -> 7.6574536 | K8: 2 | L8: 2.3 | M8: 2.9 | N8: 2 | O8: 44643 | P8: 0.48888889 | Q8: Did not record branching; Double assumed | X8: 4 - large
A9: 8 | B9: Nov '19 | C9: 11/12-20/2019 | D9: 28 | E9: F | F9: F | G9: =0.2431-J9 -> 0.2328 | H9: 0.0136 | I9: =H9/G9*100 -> 5.8419244 | J9: =0.0239-H9 -> 0.0103 | K9: 2 | L9: 2.2 | M9: 2.8 | N9: 2 | O9: 44643 | P9: 0.55208333 | Q9: Did not record branching; Double Assumed; has 8 eggs
A10: 9 | B10: Dec '19 | C10: 12/16-20/2019 | D10: 27 | E10: F | F10: F | G10: 0.3507 | H10: 0.001 | I10: =H10/G10*100 -> 0.285144 | K10: 1 | L10: 2.5 | M10: 3.2 | N10: 2 | O10: 44643 | P10: 0.55972222 | Q10: Did not record branching; Double assumed; a lot of adipose; gonad regressed; liver large and pale
A11: 10 | B11: Feb '20 | C11: 2/18-19/2020 | D11: 25 | E11: M | F11: M | G11: 0.2247 | H11: 0.0005 | I11: =H11/G11*100 -> 0.22251891 | K11: 2 | L11: 2.4 | M11: 3 | N11: 2 | O11: 44643 | P11: 0.55972222 | Q11: Did not record branching; Double assumed
A12: 11 | B12: Feb '20 | C12: 2/18-19/2020 | D12: 25 | E12: F | F12: F | G12: 0.2038 | H12: 0.015 | I12: =H12/G12*100 -> 7.360157 | K12: 2 | L12: 2.2 | M12: 2.7 | N12: 2 | O12: 44643 | P12: 0.55972222 | Q12: Did not record branching; Double assumed
A13: 12 | B13: Apr '20 | C13: 4/17-24/2020 | D13: 23 | E13: F | F13: F | G13: 0.2809 | H13: 0.0232 | I13: =H13/G13*100 -> 8.259167 | K13: 3 | L13: 2.5 | M13: 3.1 | N13: 2 | O13: 44643 | P13: 0.55972222 | Q13: Did not record branching; Double assumed
A14: 13 | B14: Apr '20 | C14: 4/17-24/2020 | D14: 23 | E14: F | F14: F | G14: 0.2539 | H14: 0.0124 | I14: =H14/G14*100 -> 4.8838125 | K14: 2 | L14: 2.4 | M14: 2.9 | N14: 2 | O14: 44643 | P14: 0.55972222 | Q14: Ovary ruptured; Did not record branching; Double assumed
A15: 14 | B15: Jun '20 | C15: 6/17-25/2020 | D15: 21 | E15: M | F15: M | G15: 0.2054 | H15: 0.001 | I15: =H15/G15*100 -> 0.48685492 | K15: 2.5 | L15: 2.4 | M15: 2.9 | N15: 2 | O15: 44643 | P15: 0.55972222 | Q15: Large gallbladder with white crystals
A16: 15 | B16: Jun '20 | C16: 6/17-25/2020 | D16: 21 | E16: F | F16: F | G16: 0.2264 | H16: 0.0133 | I16: =H16/G16*100 -> 5.8745583 | K16: 2 | L16: 2.2 | M16: 2.8 | N16: 2 | O16: 44643 | P16: 0.55972222
A17: 16 | B17: Oct '19 | C17: 10/13-15/2019 | D17: 29 | E17: F | F17: F | G17: 0.2177 | H17: 0.0057 | I17: =H17/G17*100 -> 2.618282 | K17: 1 | L17: 2.2 | M17: 2.7 | N17: 2 | O17: 44643 | P17: 0.55972222 | Q17: Anal fin damaged; slight wavy spine
A18: 17 | B18: Dec '19 | C18: 12/16-20/2019 | D18: 27 | E18: M | F18: F | G18: 0.176 | H18: 0.009 | I18: =H18/G18*100 -> 5.1136364 | K18: 1 | L18: 2.2 | M18: 2.8 | N18: 2 | O18: 44643 | P18: 0.55972222 | Q18: Papillae on anal fin, notch in dorsal fin; small follicle in gonad
A19: 18 | B19: Dec '19 | C19: 12/16-20/2019 | D19: 27 | E19: M | F19: M | G19: 0.2175 | H19: 0.0011 | I19: =H19/G19*100 -> 0.50574713 | K19: 3 | L19: 2.3 | M19: 2.9 | N19: 2 | O19: 44643 | P19: 0.55972222
A20: 19 | B20: Nov '19 | C20: 11/12-20/2019 | D20: 28 | E20: F | F20: F | G20: 0.1345 | H20: 0.0042 | I20: =H20/G20*100 -> 3.1226766 | K20: 1 | L20: 2 | M20: 2.5 | N20: 2 | O20: 44643 | P20: 0.55972222 | Q20: Slight hunchback; eyes slightly protruding
A21: 20 | B21: Nov '19 | C21: 11/12-20/2019 | D21: 28 | E21: M | F21: M | G21: 0.2672 | H21: 0.001 | I21: =H21/G21*100 -> 0.3742515 | K21: 2 | L21: 2.3 | M21: 2.9 | N21: 2 | O21: 44643 | P21: 0.55972222 | Q21: Enlarged gallbladder; highly pigmented
A22: 21 | B22: Jun '20 | C22: 6/17-25/2020 | D22: 21 | E22: F | F22: F | G22: 0.2032 | I22: =H22/G22*100 -> 0 | K22: 0 | L22: 2.1 | M22: 2.7 | N22: 2 | O22: 44643 | P22: 0.55972222 | Q22: Slight wavy spine
A23: 22 | B23: Jun '20 | C23: 6/17-25/2020 | D23: 21 | E23: M | F23: M | G23: 0.1084 | I23: =H23/G23*100 -> 0 | K23: 1 | L23: 1.8 | M23: 2.3 | N23: 2 | O23: 44643 | P23: 0.69166667
A24: 23 | B24: Aug '20 | C24: 8/14-18/2020 | D24: 19 | E24: F | F24: F | G24: 0.2356 | H24: 0.0003 | I24: =H24/G24*100 -> 0.12733447 | K24: 1 | L24: 2.3 | M24: 2.9 | N24: 2 | O24: 44643 | P24: 0.69166667 | Q24: Slight hunchback
A25: 24 | B25: Aug '20 | C25: 8/14-18/2020 | D25: 19 | E25: F | F25: F | G25: 0.2191 | H25: 0.0071 | I25: =H25/G25*100 -> 3.2405294 | K25: 2 | L25: 2.4 | M25: 3 | N25: 2 | O25: 44643 | P25: 0.69166667
A26: 25 | B26: Oct '20 | C26: 10/17-20/2020 | D26: 17 | E26: M | F26: M | G26: 0.1949 | H26: 0.0009 | I26: =H26/G26*100 -> 0.46177527 | K26: 3 | L26: 2.1 | M26: 2.7 | N26: 2 | O26: 44643 | P26: 0.69166667
A27: 26 | B27: Oct '20 | C27: 10/17-20/2020 | D27: 17 | E27: F | F27: F | G27: 0.172 | H27: 0.0074 | I27: =H27/G27*100 -> 4.3023256 | K27: 2 | L27: 2.1 | M27: 2.6 | N27: 2 | O27: 44643 | P27: 0.69166667 | Q27: Hunchback
A28: 27 | B28: Aug '20 | C28: 8/14-18/2020 | D28: 19 | E28: M | F28: M | G28: 0.1653 | H28: 0.0009 | I28: =H28/G28*100 -> 0.54446461 | K28: 2 | L28: 2 | M28: 2.5 | N28: 2 | O28: 44643 | P28: 0.69166667 | Q28: Wavy spine
A29: 28 | B29: Aug '20 | C29: 8/14-18/2020 | D29: 19 | E29: F | F29: F | G29: 0.1709 | H29: 0.0022 | I29: =H29/G29*100 -> 1.2873025 | K29: 1 | L29: 2.2 | M29: 2.8 | N29: 2 | O29: 44643 | P29: 0.69166667
A30: 29 | B30: Oct '20 | C30: 10/17-20/2020 | D30: 17 | E30: M | F30: M | G30: 0.1123 | I30: =H30/G30*100 -> 0 | K30: 1 | L30: 2 | M30: 2.5 | N30: 1 | O30: 44643 | P30: 0.69166667
A31: 30 | B31: Oct '20 | C31: 10/17-20/2020 | D31: 17 | E31: F | F31: F | G31: 0.1768 | H31: 0.0089 | I31: =H31/G31*100 -> 5.0339367 | K31: 2 | L31: 2 | M31: 2.6 | N31: 2 | O31: 44643 | P31: 0.69166667
A32: 31 | B32: Aug '20 | C32: 8/14-18/2020 | D32: 19 | E32: M | F32: M | G32: 0.1772 | H32: 0.0008 | I32: =H32/G32*100 -> 0.45146727 | K32: 3 | L32: 2.3 | M32: 2.8 | N32: 2 | O32: 44643 | P32: 0.69166667
A33: 32 | B33: Aug '20 | C33: 8/14-18/2020 | D33: 19 | E33: F | F33: F | G33: 0.2673 | H33: 0.0152 | I33: =H33/G33*100 -> 5.6864946 | K33: 3 | L33: 2.6 | M33: 3.2 | N33: 2 | O33: 44643 | P33: 0.69166667 | Q33: Many follicles, none mature; Green follicles
A34: 33 | B34: Oct '20 | C34: 10/17-20/2020 | D34: 17 | E34: M | F34: M | G34: 0.2166 | H34: 0.0018 | I34: =H34/G34*100 -> 0.83102493 | K34: 3 | L34: 2.4 | M34: 3 | N34: 2 | O34: 44643 | P34: 0.69166667
A35: 34 | B35: Oct '20 | C35: 10/17-20/2020 | D35: 17 | E35: M | F35: M | G35: 0.1539 | H35: 0.0001 | I35: =H35/G35*100 -> 0.064977258 | K35: 2 | L35: 2.2 | M35: 2.7 | N35: 2 | O35: 44643 | P35: 0.69166667 | Q35: Gonads tore
A36: 35 | B36: Oct '20 | C36: 10/17-20/2020 | D36: 17 | E36: M | F36: M | G36: 0.2452 | H36: 0.0015 | I36: =H36/G36*100 -> 0.61174551 | K36: 3 | L36: 2.3 | M36: 2.9 | N36: 2 | O36: 44643 | P36: 0.69166667
A37: 36 | B37: Nov '20 | C37: 11/13-19/2020 | D37: 16 | E37: M | F37: M | G37: 0.1486 | H37: 0.0006 | I37: =H37/G37*100 -> 0.40376851 | K37: 3 | L37: 2 | M37: 2.5 | N37: 2 | O37: 44644 | P37: 0.46180556
A38: 37 | B38: Nov '20 | C38: 11/13-19/2020 | D38: 16 | E38: F | F38: F | G38: 0.1787 | H38: 0.0094 | I38: =H38/G38*100 -> 5.2602126 | K38: 2 | L38: 2.2 | M38: 2.7 | N38: 2 | O38: 44644 | P38: 0.46944444
A39: 38 | B39: Dec '20 | C39: 12/17-21/2020 | D39: 15 | E39: F | F39: F | G39: 0.2215 | H39: 0.017 | I39: =H39/G39*100 -> 7.6749436 | K39: 2 | L39: 2.3 | M39: 2.9 | N39: 2 | O39: 44644 | P39: 0.47708333
A40: 39 | B40: Dec '20 | C40: 12/17-21/2020 | D40: 15 | E40: F | F40: F | G40: 0.2364 | H40: 0.0344 | I40: =H40/G40*100 -> 14.551607 | K40: 3 | L40: 2.2 | M40: 2.7 | N40: 2 | O40: 44644 | P40: 0.48402778 | Q40: Egg bound
...

Sheet DNA RNA Conc.
A1: ID | B1: Age | C1: Sex | D1: DNA Suspended in: | E1: DNA Extraction Date | F1: DNA Conc (ng/ul) | G1: DNA/280 | H1: DNA/230 | I1: DNA Volume(ul) | J1: Total DNA (ng) | K1: RNA Extraction Date | L1: RNA Suspended in: | M1: RNA Conc (ng/ul) | N1: RNA/280 | O1: RNA/230 | P1: RNA Volume(ul) | Q1: Total RNA (ng)
A2: 1 | B2: 29 | C2: =VLOOKUP(A2, Dissect!A:Q, 6) -> M | D2: TE | E2: 44881 | F2: 84.9 | G2: 1.9 | H2: 1.4 | I2: 48.5 | J2: =I2*F2 -> 4117.65 | K2: 44895 | L2: FAMQ | M2: 206 | N2: 2.2 | O2: 2.25 | P2: 43.5 | Q2: =M2*P2 -> 8961
A3: 2 | B3: 28 | C3: =VLOOKUP(A3, Dissect!A:Q, 6) -> M | D3: TE | E3: 44881 | F3: 306 | G3: 1.9 | H3: 2.3 | I3: 48.5 | J3: =I3*F3 -> 14841 | K3: 44895 | L3: FAMQ | M3: 297 | N3: 2.2 | O3: 2.02 | P3: 43.5 | Q3: =M3*P3 -> 12919.5
A4: 3 | B4: 27 | C4: =VLOOKUP(A4, Dissect!A:Q, 6) -> M | D4: TE | E4: 44881 | F4: 35 | G4: 1.9 | H4: -24 | I4: 48.5 | J4: =I4*F4 -> 1697.5 | K4: 44895 | L4: FAMQ | M4: 31 | N4: 2.1 | O4: 1.57 | P4: 43.5 | Q4: =M4*P4 -> 1348.5
A5: 4 | B5: 25 | C5: =VLOOKUP(A5, Dissect!A:Q, 6) -> F | D5: TE | E5: 44881 | F5: 126 | G5: 1.9 | H5: 0.2 | I5: 48.5 | J5: =I5*F5 -> 6111 | K5: 44895 | L5: FAMQ | M5: 195 | N5: 2.2 | O5: 1.45 | P5: 43.5 | Q5: =M5*P5 -> 8482.5
A6: 5 | B6: 23 | C6: =VLOOKUP(A6, Dissect!A:Q, 6) -> F | D6: TE | E6: 44881 | F6: 60 | G6: 1.9 | H6: 7.3 | I6: 48.5 | J6: =I6*F6 -> 2910 | K6: 44895 | L6: FAMQ | M6: 246 | N6: 2.2 | O6: 1.87 | P6: 43.5 | Q6: =M6*P6 -> 10701
A7: 6 | B7: 21 | C7: =VLOOKUP(A7, Dissect!A:Q, 6) -> F | D7: TE | E7: 44881 | F7: 216 | G7: 1.9 | H7: 1.5 | I7: 48.5 | J7: =I7*F7 -> 10476 | K7: 44895 | L7: FAMQ | M7: 592 | N7: 2.2 | O7: 2.19 | P7: 43.5 | Q7: =M7*P7 -> 25752
A8: 7 | B8: 29 | C8: =VLOOKUP(A8, Dissect!A:Q, 6) -> F | D8: TE | E8: 44881 | F8: 100 | G8: 1.9 | H8: 3.1 | I8: 48.5 | J8: =I8*F8 -> 4850 | K8: 44895 | L8: FAMQ | M8: 390 | N8: 2.2 | O8: 2.21 | P8: 43.5 | Q8: =M8*P8 -> 16965
A9: 8 | B9: 28 | C9: =VLOOKUP(A9, Dissect!A:Q, 6) -> F | D9: TE | E9: 44881 | F9: 95 | G9: 1.9 | H9: 1.2 | I9: 48.5 | J9: =I9*F9 -> 4607.5 | K9: 44895 | L9: FAMQ | M9: 923 | N9: 2.2 | O9: 2.06 | P9: 43.5 | Q9: =M9*P9 -> 40150.5
A10: 9 | B10: 27 | C10: =VLOOKUP(A10, Dissect!A:Q, 6) -> F | D10: TE | E10: 44881 | F10: 324 | G10: 2 | H10: 2.6 | I10: 48.5 | J10: =I10*F10 -> 15714 | K10: 44895 | L10: FAMQ | M10: 488 | N10: 2.2 | O10: 2.22 | P10: 43.5 | Q10: =M10*P10 -> 21228
A11: 10 | B11: 25 | C11: =VLOOKUP(A11, Dissect!A:Q, 6) -> M | D11: TE | E11: 44881 | F11: 266 | G11: 1.9 | H11: 1.7 | I11: 48.5 | J11: =I11*F11 -> 12901 | K11: 44895 | L11: FAMQ | M11: 604 | N11: 2.2 | O11: 2.28 | P11: 43.5 | Q11: =M11*P11 -> 26274
A12: 11 | B12: 25 | C12: =VLOOKUP(A12, Dissect!A:Q, 6) -> F | D12: TE | E12: 44881 | F12: 94 | G12: 1.9 | H12: 4.5 | I12: 48.5 | J12: =I12*F12 -> 4559 | K12: 44895 | L12: FAMQ | M12: 594 | N12: 2.2 | O12: 2.25 | P12: 43.5 | Q12: =M12*P12 -> 25839
A13: 12 | B13: 23 | C13: =VLOOKUP(A13, Dissect!A:Q, 6) -> F | D13: TE | E13: 44881 | F13: 113 | G13: 1.9 | H13: 3.4 | I13: 48.5 | J13: =I13*F13 -> 5480.5 | K13: 44895 | L13: FAMQ | M13: 499 | N13: 2.2 | O13: 1.94 | P13: 43.5 | Q13: =M13*P13 -> 21706.5
... A17: 16 | B17: 29 | C17: =VLOOKUP(A17, Dissect!A:Q, 6) -> F | D17: TE | E17: 44881 | F17: 150 | G17: 1.9 | H17: 2.7 | I17: 48.5 | J17: =I17*F17 -> 7275 | K17: 44895 | L17: FAMQ | M17: 531 | N17: 2.2 | O17: 2.16 | P17: 43.5 | Q17: =M17*P17 -> 23098.5
A18: 17 | B18: 27 | C18: F | D18: TE | E18: 44881 | F18: 93 | G18: 1.9 | H18: 3.4 | I18: 48.5 | J18: =I18*F18 -> 4510.5 | K18: 44895 | L18: FAMQ | M18: 211 | N18: 2.2 | O18: 2.21 | P18: 43.5 | Q18: =M18*P18 -> 9178.5
A19: 18 | B19: 27 | C19: =VLOOKUP(A19, Dissect!A:Q, 6) -> M | D19: TE | E19: 44881 | F19: 135 | G19: 1.9 | H19: 3.7 | I19: 48.5 | J19: =I19*F19 -> 6547.5 | K19: 44895 | L19: FAMQ | M19: 303 | N19: 2.2 | O19: 2.14 | P19: 43.5 | Q19: =M19*P19 -> 13180.5
A20: 19 | B20: 28 | C20: =VLOOKUP(A20, Dissect!A:Q, 6) -> F | D20: TE | E20: 44881 | F20: 56 | G20: 1.9 | H20: 0.4 | I20: 48.5 | J20: =I20*F20 -> 2716 | K20: 44895 | L20: FAMQ | M20: 216 | N20: 2.2 | O20: 1.99 | P20: 43.5 | Q20: =M20*P20 -> 9396
A21: 20 | B21: 28 | C21: =VLOOKUP(A21, Dissect!A:Q, 6) -> M | D21: TE | E21: 44881 | F21: 145 | G21: 1.9 | H21: 3.2 | I21: 48.5 | J21: =I21*F21 -> 7032.5 | K21: 44895 | L21: FAMQ | M21: 406 | N21: 2.2 | O21: 2.18 | P21: 43.5 | Q21: =M21*P21 -> 17661
A22: 21 | B22: 21 | C22: =VLOOKUP(A22, Dissect!A:Q, 6) -> F | D22: TE | E22: 44881 | F22: 21 | G22: 1.8 | H22: -2 | I22: 48.5 | J22: =I22*F22 -> 1018.5 | K22: 44895 | L22: FAMQ | M22: 93 | N22: 2.1 | O22: 2.08 | P22: 43.5 | Q22: =M22*P22 -> 4045.5
A23: 22 | B23: 21 | C23: =VLOOKUP(A23, Dissect!A:Q, 6) -> M | D23: TE | E23: 44881 | F23: 112 | G23: 1.9 | H23: 3.3 | I23: 48.5 | J23: =I23*F23 -> 5432 | K23: 44895 | L23: FAMQ | M23: 100 | N23: 2.1 | O23: 1.56 | P23: 43.5 | Q23: =M23*P23 -> 4350
A24: 23 | B24: 19 | C24: =VLOOKUP(A24, Dissect!A:Q, 6) -> F | D24: TE | E24: 44881 | F24: 72 | G24: 1.9 | H24: 5.6 | I24: 48.5 | J24: =I24*F24 -> 3492 | K24: 44895 | L24: FAMQ | M24: 144 | N24: 2.1 | O24: 1.8 | P24: 43.5 | Q24: =M24*P24 -> 6264
A25: 24 | B25: 19 | C25: =VLOOKUP(A25, Dissect!A:Q, 6) -> F | D25: TE | E25: 44881 | F25: 151 | G25: 1.9 | H25: 0.75 | I25: 48.5 | J25: =I25*F25 -> 7323.5 | K25: 44895 | L25: FAMQ | M25: 624 | N25: 2.2 | O25: 1.9 | P25: 43.5 | Q25: =M25*P25 -> 27144
A26: 25 | B26: 17 | C26: =VLOOKUP(A26, Dissect!A:Q, 6) -> M | D26: TE | E26: 44881 | F26: 90 | G26: 1.9 | H26: 3.9 | I26: 48.5 | J26: =I26*F26 -> 4365 | K26: 44896 | L26: FAMQ | M26: 240 | N26: 2.1 | O26: 1.95 | P26: 43.5 | Q26: =M26*P26 -> 10440
A27: 26 | B27: 17 | C27: =VLOOKUP(A27, Dissect!A:Q, 6) -> F | D27: TE | E27: 44881 | F27: 70 | G27: 1.9 | H27: 3.9 | I27: 48.5 | J27: =I27*F27 -> 3395 | K27: 44896 | L27: FAMQ | M27: 362 | N27: 2.2 | O27: 1.96 | P27: 43.5 | Q27: =M27*P27 -> 15747
A28: 27 | B28: 19 | C28: =VLOOKUP(A28, Dissect!A:Q, 6) -> M | D28: TE | E28: 44881 | F28: 57 | G28: 1.9 | H28: 6 | I28: 48.5 | J28: =I28*F28 -> 2764.5 | K28: 44896 | L28: FAMQ | M28: 140 | N28: 2.2 | O28: 2.1 | P28: 43.5 | Q28: =M28*P28 -> 6090
A29: 28 | B29: 19 | C29: =VLOOKUP(A29, Dissect!A:Q, 6) -> F | D29: TE | E29: 44881 | F29: 128 | G29: 1.9 | H29: 2.9 | I29: 48.5 | J29: =I29*F29 -> 6208 | K29: 44896 | L29: FAMQ | M29: 225 | N29: 2.2 | O29: 2.2 | P29: 43.5 | Q29: =M29*P29 -> 9787.5
A30: 29 | B30: 17 | C30: =VLOOKUP(A30, Dissect!A:Q, 6) -> M | D30: TE | E30: 44881 | F30: 73 | G30: 1.9 | H30: 3.3 | I30: 48.5 | J30: =I30*F30 -> 3540.5 | K30: 44896 | L30: FAMQ | M30: 190 | N30: 2 | O30: 1.2 | P30: 43.5 | Q30: =M30*P30 -> 8265
... A58: 57 | B58: 12 | C58: =VLOOKUP(A58, Dissect!A:Q, 6) -> F | D58: FAMQ | E58: 44902 | F58: 131 | G58: 2 | H58: 2.3 | I58: 48.5 | J58: =I58*F58 -> 6353.5 | K58: 44908 | L58: FAMQ | M58: 690 | N58: 2.2 | O58: 2.3 | P58: 43.5 | Q58: =M58*P58 -> 30015
A59: 58 | B59: 12 | C59: =VLOOKUP(A59, Dissect!A:Q, 6) -> M | D59: FAMQ | E59: 44902 | F59: 4 | G59: 1.5 | H59: 0.8 | I59: 48.5 | J59: =I59*F59 -> 194 | K59: 44908 | L59: FAMQ | P59: 43.5 | Q59: =M59*P59 -> 0
A60: 59 | B60: 10 | C60: =VLOOKUP(A60, Dissect!A:Q, 6) -> M | D60: FAMQ | E60: 44902 | F60: 54 | G60: 1.9 | H60: 2.1 | I60: 48.5 | J60: =I60*F60 -> 2619 | K60: 44908 | L60: FAMQ | M60: 138 | N60: 2.2 | O60: 2.1 | P60: 43.5 | Q60: =M60*P60 -> 6003
A61: 60 | B61: 10 | C61: =VLOOKUP(A61, Dissect!A:Q, 6) -> F | D61: FAMQ | E61: 44902 | F61: 70 | G61: 1.9 | H61: 1.2 | I61: 48.5 | J61: =I61*F61 -> 3395 | K61: 44908 | L61: FAMQ | M61: 480 | N61: 2.2 | O61: 2.1 | P61: 43.5 | Q61: =M61*P61 -> 20880
A62: 61 | B62: 9 | C62: =VLOOKUP(A62, Dissect!A:Q, 6) -> M | D62: FAMQ | E62: 44902 | F62: 113 | G62: 1.9 | H62: 1.3 | I62: 48.5 | J62: =I62*F62 -> 5480.5 | K62: 44908 | L62: FAMQ | M62: 247 | N62: 2.2 | O62: 2.2 | P62: 43.5 | Q62: =M62*P62 -> 10744.5
A63: 62 | B63: 9 | C63: =VLOOKUP(A63, Dissect!A:Q, 6) -> F | D63: FAMQ | E63: 44902 | F63: 104 | G63: 2 | H63: 2.2 | I63: 48.5 | J63: =I63*F63 -> 5044 | K63: 44908 | L63: FAMQ | M63: 557 | N63: 2.2 | O63: 2.2 | P63: 43.5 | Q63: =M63*P63 -> 24229.5
A64: 63 | B64: 12 | C64: =VLOOKUP(A64, Dissect!A:Q, 6) -> F | D64: FAMQ | E64: 44902 | F64: 70 | G64: 1.9 | H64: 0.9 | I64: 48.5 | J64: =I64*F64 -> 3395 | K64: 44908 | L64: FAMQ | M64: 401 | N64: 2.2 | O64: 1.8 | P64: 43.5 | Q64: =M64*P64 -> 17443.5
A65: 64 | B65: 12 | C65: =VLOOKUP(A65, Dissect!A:Q, 6) -> F | D65: FAMQ | E65: 44902 | F65: 109 | G65: 2 | H65: 2.2 | I65: 48.5 | J65: =I65*F65 -> 5286.5 | K65: 44908 | L65: FAMQ | M65: 625 | N65: 2.2 | O65: 2.2 | P65: 43.5 | Q65: =M65*P65 -> 27187.5
A66: 65 | B66: 10 | C66: =VLOOKUP(A66, Dissect!A:Q, 6) -> M | D66: FAMQ | E66: 44902 | F66: 89 | G66: 1.9 | H66: 2.2 | I66: 48.5 | J66: =I66*F66 -> 4316.5 | K66: 44908 | L66: FAMQ | M66: 287 | N66: 2.2 | O66: 2.1 | P66: 43.5 | Q66: =M66*P66 -> 12484.5
A67: 66 | B67: 10 | C67: =VLOOKUP(A67, Dissect!A:Q, 6) -> M | D67: FAMQ | E67: 44902 | F67: 34 | G67: 1.8 | H67: 1.4 | I67: 48.5 | J67: =I67*F67 -> 1649 | K67: 44908 | L67: FAMQ | M67: 107 | N67: 2.2 | O67: 1.9 | P67: 43.5 | Q67: =M67*P67 -> 4654.5
A68: 67 | B68: 9 | C68: =VLOOKUP(A68, Dissect!A:Q, 6) -> F | D68: FAMQ | E68: 44902 | F68: 57 | G68: 1.9 | H68: 1.8 | I68: 48.5 | J68: =I68*F68 -> 2764.5 | K68: 44908 | L68: FAMQ | M68: 384 | N68: 2.2 | O68: 2.2 | P68: 43.5 | Q68: =M68*P68 -> 16704
A69: 68 | B69: 9 | C69: =VLOOKUP(A69, Dissect!A:Q, 6) -> F | D69: FAMQ | E69: 44902 | F69: 516 | G69: 2.1 | H69: 2.3 | I69: 48.5 | J69: =I69*F69 -> 25026 | K69: 44908 | L69: FAMQ | M69: 716 | N69: 2.2 | O69: 2.3 | P69: 43.5 | Q69: =M69*P69 -> 31146
A70: 69 | B70: 12 | C70: =VLOOKUP(A70, Dissect!A:Q, 6) -> F | D70: FAMQ | E70: 44902 | F70: 117 | G70: 2 | H70: 2.2 | I70: 48.5 | J70: =I70*F70 -> 5674.5 | K70: 44908 | L70: FAMQ | M70: 1771 | N70: 2.1 | O70: 2.2 | P70: 43.5 | Q70: =M70*P70 -> 77038.5
...

Sheet Sample size table
A3: Count of ID | B3: Sex
A4: Age (months) | B4: F | C4: M | D4: Total Result
A5: 2 | B5: 2 | C5: 2 | D5: 4
A6: 3 | B6: 3 | C6: 2 | D6: 5
A7: 4 | B7: 3 | C7: 3 | D7: 6
A8: 5 | B8: 3 | C8: 3 | D8: 6
A9: 6 | B9: 1 | C9: 1 | D9: 2
A10: 7 | B10: 3 | C10: 4 | D10: 7
A11: 8 | B11: 3 | C11: 3 | D11: 6
A12: 9 | B12: 3 | C12: 3 | D12: 6
A13: 10 | B13: 2 | C13: 3 | D13: 5
A14: 14 | B14: 4 | C14: 4 | D14: 8
A15: 15 | B15: 3 | D15: 3
A16: 16 | B16: 3 | C16: 4 | D16: 7
A17: 17 | B17: 2 | C17: 5 | D17: 7
A18: 19 | B18: 3 | C18: 2 | D18: 5
A19: 21 | B19: 2 | C19: 2 | D19: 4
A20: 23 | B20: 2 | D20: 2
A21: 25 | B21: 1 | C21: 1 | D21: 2
A22: 27 | B22: 2 | C22: 2 | D22: 4
A23: 28 | B23: 2 | C23: 2 | D23: 4
A24: 29 | B24: 2 | C24: 1 | D24: 3
A25: Total Result | B25: 49 | C25: 47 | D25: 96

Sheet Samples for Sequencing
A1: ID | B1: Age (months) | C1: Sex | D1: DNA Suspended in: | E1: DNA Extraction Date | F1: DNA Conc (ng/ul) | G1: DNA/280 | H1: DNA/230 | I1: Volume(ul) | J1: Total DNA (ng) | K1: RNA Extraction Date | L1: RNA Suspended in: | M1: RNA Conc (ng/ul) | N1: RNA/280 | O1: RNA/230 | P1: Volume(ul) | Q1: Total RNA (ng)
A2: 1 | B2: 29 | C2: M | D2: TE | E2: 44881 | F2: 84.9 | G2: 1.9 | H2: 1.4 | I2: 48.5 | J2: 4117.65 | K2: 44895 | L2: FAMQ | M2: 206 | N2: 2.2 | O2: 2.25 | P2: 43.5 | Q2: 8961 | S2: Precip Both
A3: 2 | B3: 28 | C3: M | D3: TE | E3: 44881 | F3: 306 | G3: 1.9 | H3: 2.3 | I3: 48.5 | J3: 14841 | K3: 44895 | L3: FAMQ | M3: 297 | N3: 2.2 | O3: 2.02 | P3: 43.5 | Q3: 12919.5 | S3: Just DNA
A4: 3 | B4: 27 | C4: M | D4: TE | E4: 44881 | F4: 35 | G4: 1.9 | H4: -24 | I4: 48.5 | J4: 1697.5 | K4: 44895 | L4: FAMQ | M4: 31 | N4: 2.1 | O4: 1.57 | P4: 43.5 | Q4: 1348.5
A5: 6 | B5: 21 | C5: F | D5: TE | E5: 44881 | F5: 216 | G5: 1.9 | H5: 1.5 | I5: 48.5 | J5: 10476 | K5: 44895 | L5: FAMQ | M5: 592 | N5: 2.2 | O5: 2.19 | P5: 43.5 | Q5: 25752
A6: 7 | B6: 29 | C6: F | D6: TE | E6: 44881 | F6: 100 | G6: 1.9 | H6: 3.1 | I6: 48.5 | J6: 4850 | K6: 44895 | L6: FAMQ | M6: 390 | N6: 2.2 | O6: 2.21 | P6: 43.5 | Q6: 16965
A7: 8 | B7: 28 | C7: F | D7: TE | E7: 44881 | F7: 95 | G7: 1.9 | H7: 1.2 | I7: 48.5 | J7: 4607.5 | K7: 44895 | L7: FAMQ | M7: 923 | N7: 2.2 | O7: 2.06 | P7: 43.5 | Q7: 40150.5
A8: 9 | B8: 27 | C8: F | D8: TE | E8: 44881 | F8: 324 | G8: 2 | H8: 2.6 | I8: 48.5 | J8: 15714 | K8: 44895 | L8: FAMQ | M8: 488 | N8: 2.2 | O8: 2.22 | P8: 43.5 | Q8: 21228
A9: 10 | B9: 25 | C9: M | D9: TE | E9: 44881 | F9: 266 | G9: 1.9 | H9: 1.7 | I9: 48.5 | J9: 12901 | K9: 44895 | L9: FAMQ | M9: 604 | N9: 2.2 | O9: 2.28 | P9: 43.5 | Q9: 26274
A10: 11 | B10: 25 | C10: =VLOOKUP(A10, Dissect!A:Q, 6) -> F | D10: TE | E10: 44881 | F10: 94 | G10: 1.9 | H10: 4.5 | I10: 48.5 | J10: =I10*F10 -> 4559 | K10: 44895 | L10: FAMQ | M10: 594 | N10: 2.2 | O10: 2.25 | P10: 43.5 | Q10: =M10*P10 -> 25839
A11: 12 | B11: 23 | C11: F | D11: TE | E11: 44881 | F11: 113 | G11: 1.9 | H11: 3.4 | I11: 48.5 | J11: 5480.5 | K11: 44895 | L11: FAMQ | M11: 499 | N11: 2.2 | O11: 1.94 | P11: 43.5 | Q11: 21706.5
A12: 13 | B12: 23 | C12: F | D12: TE | E12: 44881 | F12: 90 | G12: 1.9 | H12: 4.6 | I12: 48.5 | J12: 4365 | K12: 44895 | L12: FAMQ | M12: 352 | N12: 2.2 | O12: 0.54 | P12: 43.5 | Q12: 15312
A13: 14 | B13: 21 | C13: M | D13: TE | E13: 44881 | F13: 127 | G13: 1.9 | H13: 3.3 | I13: 48.5 | J13: 6159.5 | K13: 44895 | L13: FAMQ | M13: 342 | N13: 2.2 | O13: 1.98 | P13: 43.5 | Q13: 14877
A14: 15 | B14: 21 | C14: F | D14: TE | E14: 44881 | F14: 60 | G14: 1.9 | H14: 4.3 | I14: 48.5 | J14: 2910 | K14: 44895 | L14: FAMQ | M14: 969 | N14: 2.2 | O14: 2.21 | P14: 43.5 | Q14: 42151.5
A15: 16 | B15: 29 | C15: F | D15: TE | E15: 44881 | F15: 150 | G15: 1.9 | H15: 2.7 | I15: 48.5 | J15: 7275 | K15: 44895 | L15: FAMQ | M15: 531 | N15: 2.2 | O15: 2.16 | P15: 43.5 | Q15: 23098.5
A16: 17 | B16: 27 | C16: F | D16: TE | E16: 44881 | F16: 93 | G16: 1.9 | H16: 3.4 | I16: 48.5 | J16: 4510.5 | K16: 44895 | L16: FAMQ | M16: 211 | N16: 2.2 | O16: 2.21 | P16: 43.5 | Q16: 9178.5
A17: 18 | B17: 27 | C17: M | D17: TE | E17: 44881 | F17: 135 | G17: 1.9 | H17: 3.7 | I17: 48.5 | J17: 6547.5 | K17: 44895 | L17: FAMQ | M17: 303 | N17: 2.2 | O17: 2.14 | P17: 43.5 | Q17: 13180.5
A18: 19 | B18: 28 | C18: F | D18: TE | E18: 44881 | F18: 56 | G18: 1.9 | H18: 0.4 | I18: 48.5 | J18: 2716 | K18: 44895 | L18: FAMQ | M18: 216 | N18: 2.2 | O18: 1.99 | P18: 43.5 | Q18: 9396
A19: 20 | B19: 28 | C19: M | D19: TE | E19: 44881 | F19: 145 | G19: 1.9 | H19: 3.2 | I19: 48.5 | J19: 7032.5 | K19: 44895 | L19: FAMQ | M19: 406 | N19: 2.2 | O19: 2.18 | P19: 43.5 | Q19: 17661
A20: 22 | B20: 21 | C20: M | D20: TE | E20: 44881 | F20: 112 | G20: 1.9 | H20: 3.3 | I20: 48.5 | J20: 5432 | K20: 44895 | L20: FAMQ | M20: 100 | N20: 2.1 | O20: 1.56 | P20: 43.5 | Q20: 4350
A21: 24 | B21: 19 | C21: F | D21: TE | E21: 44881 | F21: 151 | G21: 1.9 | H21: 0.75 | I21: 48.5 | J21: 7323.5 | K21: 44895 | L21: FAMQ | M21: 624 | N21: 2.2 | O21: 1.9 | P21: 43.5 | Q21: 27144
A22: 25 | B22: 17 | C22: M | D22: TE | E22: 44881 | F22: 90 | G22: 1.9 | H22: 3.9 | I22: 48.5 | J22: 4365 | K22: 44896 | L22: FAMQ | M22: 240 | N22: 2.1 | O22: 1.95 | P22: 43.5 | Q22: 10440
... A64: 78 | B64: 7 | C64: F | D64: FAMQ | E64: 44902 | F64: 181 | G64: 2 | H64: 2.3 | I64: 48.5 | J64: 8778.5 | K64: 44910 | L64: FAMQ | M64: 467 | N64: 2.2 | O64: 2.2 | P64: 43.5 | Q64: 20314.5
A65: 81 | B65: 6 | C65: =VLOOKUP(A65, Dissect!A:Q, 6) -> M | D65: FAMQ | E65: 44902 | F65: 280 | G65: 2 | H65: 2 | I65: 48.5 | J65: =I65*F65 -> 13580 | K65: 44910 | L65: FAMQ | M65: 127 | N65: 2.2 | O65: 2.1 | P65: 43.5 | Q65: =M65*P65 -> 5524.5
A66: 82 | B66: 8 | C66: F | D66: FAMQ | E66: 44902 | F66: 104 | G66: 2 | H66: 2.3 | I66: 48.5 | J66: 5044 | K66: 44910 | L66: FAMQ | M66: 291 | N66: 2.2 | O66: 2.1 | P66: 43.5 | Q66: 12658.5
A67: 83 | B67: 8 | C67: M | D67: FAMQ | E67: 44902 | F67: 20 | G67: 1.8 | H67: 1.7 | I67: 48.5 | J67: 970 | K67: 44910 | L67: FAMQ | M67: 51 | N67: 2.1 | O67: 1.5 | P67: 43.5 | Q67: 2218.5
A68: 85 | B68: 7 | C68: F | D68: FAMQ | E68: 44902 | F68: 104 | G68: 7.9 | H68: 2.3 | I68: 48.5 | J68: 5044 | K68: 44910 | L68: FAMQ | M68: 314 | N68: 2.2 | O68: 2.1 | P68: 43.5 | Q68: 13659
A69: 87 | B69: 6 | C69: F | D69: FAMQ | E69: 44902 | F69: 193 | G69: 2 | H69: 2.3 | I69: 48.5 | J69: 9360.5 | K69: 44910 | L69: FAMQ | M69: 195 | N69: 2.2 | O69: 2.1 | P69: 43.5 | Q69: 8482.5
A70: 88 | B70: 8 | C70: M | D70: FAMQ | E70: 44902 | F70: 70 | G70: 1.9 | H70: 2.1 | I70: 48.5 | J70: 3395 | K70: 44910 | L70: FAMQ | M70: 163 | N70: 2.2 | O70: 2.2 | P70: 43.5 | Q70: 7090.5
A71: 90 | B71: 7 | C71: M | D71: FAMQ | E71: 44902 | F71: 51 | G71: 1.9 | H71: 1.5 | I71: 48.5 | J71: 2473.5 | K71: 44910 | L71: FAMQ | M71: 98 | N71: 2.2 | O71: 2 | P71: 43.5 | Q71: 4263
A72: 91 | B72: 7 | C72: F | D72: FAMQ | E72: 44902 | F72: 143 | G72: 1.9 | H72: 2.3 | I72: 48.5 | J72: 6935.5 | K72: 44910 | L72: FAMQ | M72: 243 | N72: 2.2 | O72: 1.9 | P72: 43.5 | Q72: 10570.5
A73: 94 | B73: 8 | C73: M | D73: FAMQ | E73: 44902 | F73: 111 | G73: 1.9 | H73: 2.2 | I73: 48.5 | J73: 5383.5 | K73: 44910 | L73: FAMQ | M73: 180 | N73: 2.2 | O73: 2.2 | P73: 43.5 | Q73: 7830
A74: 95 | B74: 7 | C74: M | D74: FAMQ | E74: 44902 | F74: 49 | G74: 2 | H74: 2.1 | I74: 48.5 | J74: 2376.5 | K74: 44910 | L74: FAMQ | M74: 81 | N74: 2.1 | O74: 0.4 | P74: 43.5 | Q74: 3523.5
A75: 98 | B75: 5 | C75: M | D75: FAMQ | E75: 44914 | F75: 114 | G75: 1.9 | H75: 0.2 | I75: 48.5 | J75: 5529 | K75: 44916 | L75: FAMQ | M75: 243 | N75: 2.2 | O75: 2.1 | P75: 43.5 | Q75: 10570.5
A76: 99 | B76: 7 | C76: M | D76: FAMQ | E76: 44914 | F76: 47 | G76: 1.9 | H76: 0.2 | I76: 48.5 | J76: 2279.5 | K76: 44916 | L76: FAMQ | M76: 110 | N76: 2.2 | O76: 1.8 | P76: 43.5 | Q76: 4785
A77: 100 | B77: 7 | C77: M | D77: FAMQ | E77: 44914 | F77: 38 | G77: 1.9 | H77: 0.1 | I77: 48.5 | J77: 1843 | K77: 44916 | L77: FAMQ | M77: 122 | N77: 2.2 | O77: 1.3 | P77: 43.5 | Q77: 5307
... A97: 140 | B97: 2 | C97: M | D97: FAMQ | E97: 44914 | F97: 43 | G97: 1.9 | H97: 0.3 | I97: 48.5 | J97: 2085.5 | K97: 44916 | L97: FAMQ | M97: 141 | N97: 2.2 | O97: 1.7 | P97: 43.5 | Q97: 6133.5

Sheet Telo_ID
A1: Fish_ID | B1: Rand_ID | C1: Plate | D1: Sample | E1: Final_ID
A2: 52 | B2: 1 | C2: P1 | D2: Unkn-01 | E2: =CONCATENATE(C2, "-", D2) -> P1-Unkn-01
A3: 35 | B3: 2 | C3: P1 | D3: Unkn-02 | E3: =CONCATENATE(C3, "-", D3) -> P1-Unkn-02
A4: 3 | B4: 3 | C4: P1 | D4: Unkn-03 | E4: =CONCATENATE(C4, "-", D4) -> P1-Unkn-03
A5: 108 | B5: 4 | C5: P1 | D5: Unkn-04 | E5: =CONCATENATE(C5, "-", D5) -> P1-Unkn-04
A6: 93 | B6: 5 | C6: P1 | D6: Unkn-05 | E6: =CONCATENATE(C6, "-", D6) -> P1-Unkn-05
A7: 138 | B7: 6 | C7: P1 | D7: Unkn-06 | E7: =CONCATENATE(C7, "-", D7) -> P1-Unkn-06
A8: 4 | B8: 7 | C8: P1 | D8: Unkn-07 | E8: =CONCATENATE(C8, "-", D8) -> P1-Unkn-07
A9: 16 | B9: 8 | C9: P1 | D9: Unkn-08 | E9: =CONCATENATE(C9, "-", D9) -> P1-Unkn-08
A10: 128 | B10: 9 | C10: P1 | D10: Unkn-09 | E10: =CONCATENATE(C10, "-", D10) -> P1-Unkn-09
A11: 123 | B11: 10 | C11: P1 | D11: Unkn-10 | E11: =CONCATENATE(C11, "-", D11) -> P1-Unkn-10
A12: 43 | B12: 11 | C12: P1 | D12: Unkn-11 | E12: =CONCATENATE(C12, "-", D12) -> P1-Unkn-11
A13: 42 | B13: 12 | C13: P1 | D13: Unkn-12 | E13: =CONCATENATE(C13, "-", D13) -> P1-Unkn-12
... A118: 19 | B118: 117 | C118: P6 | D118: Unkn-12 | E118: =CONCATENATE(C118, "-", D118) -> P6-Unkn-12
